Workbook
Name Rýchly_filter_obdobie: #N/A

Sheet Postup
A2: pri účtovaní FA od ŽN - ku každej FA musí byť priložený PROTOKOL O ZADANÍ A PREVZATÍ PRÁC k Rámcovej zmluve o dielo
A3: ( suma na Protokole musí sedieť aj s úhradmi výkonov v IN TIME ). Ak suma sedí, do poznámky uvádzam č. FA prislúchajúcej k Protokolu.
A4: Ak suma nesedí, riešiť s vedúcimi príslušnej VP.
A48: Pri zúčtovaní všetkých FA za predchádzajúci mesiac k ukončeným zákazkam robím NEVYFAKTUROVANÉ DODÁVKY.
A49: ABRA = rad dokladu: UMaO = dátum vystav.dokladu: dám dátum od roku trvania zákazky do dátumu ukončenia zákazky = vybavené objednávky: dám NIE = riadky: vyberiem všetky zákazky zo zoznamu
A50: ukončených zákaziek, vysvietim si INSERTOM a dám získať záznamy.
A51: Nevyfakturované objednávky riešiť s koordinátormi.
A52: Účtujem cez INT-/2019 k 31. príslušného mesiaca
B53: 518xxx/326100 + zákazka!!! (na jednotlivé eurá a zákazky)
A54: Keď príde FPR tak zúčtujem 326100/321010 - tuzemsko, 321020 - zahraničie)
A56: ZOZNAM UKONČENÝCH ZÁKAZIEK
A57: Na serveri v priečinku PREHĽADY - excelovský súbor EXPEDÍCIE (vyfiltrujem si iba ukončené zákazky za príslušný mesiac)
A58: Poslať riaditeľovi na doplnenie kalkulácie.

Sheet data_z_viacur.zostavy
A1: Zákazka | B1: Názov zákazky | C1: Výrobný úsek | D1: Kategória | E1: Stredisko | F1: ZF [hod] | G1: NC [hod] | H1: Spolu [hod] | I1: obdobie | J1: Zakazka_upr | K1: cd_typ_Zákazky | L1: nm_typ_zákazky
A2: 23/0082 | B2: Základový rám 1 ks | C2: VP2 | D2: JR | E2: Zámočník | F2: 4 | G2: 0 | H2: 4 | I2: 2026/06 | J2: =TRIM(A2) -> 23/0082 | K2: =MID(J2,4,1) -> 0 | L2: =IF(K2="9","9_podnik. Réžia",IF(K2="5","5_režijné zákazky",IF(K2="8","8_drobné zákazky",IF(K2="7","7_Vyskum_a_vyvoj","jednicové zákazky")))) -> jednicové zákazky
A3: 23/0082 | B3: Základový rám 1 ks | C3: VP2 | D3: ŽN | E3: Zám. po zvár. | F3: 6 | G3: 0 | H3: 6 | I3: 2026/06 | J3: =TRIM(A3) -> 23/0082 | K3: =MID(J3,4,1) -> 0 | L3: =IF(K3="9","9_podnik. Réžia",IF(K3="5","5_režijné zákazky",IF(K3="8","8_drobné zákazky",IF(K3="7","7_Vyskum_a_vyvoj","jednicové zákazky")))) -> jednicové zákazky
A4: 23/0082 | B4: Základový rám 1 ks | C4: VP5 | D4: JR | E4: Apretúra | F4: 48 | G4: 0 | H4: 48 | I4: 2026/06 | J4: =TRIM(A4) -> 23/0082 | K4: =MID(J4,4,1) -> 0 | L4: =IF(K4="9","9_podnik. Réžia",IF(K4="5","5_režijné zákazky",IF(K4="8","8_drobné zákazky",IF(K4="7","7_Vyskum_a_vyvoj","jednicové zákazky")))) -> jednicové zákazky
A5: 23/0082 | B5: Základový rám 1 ks | C5: VP5 | D5: JR | E5: Lakovanie | F5: 8 | G5: 0 | H5: 8 | I5: 2026/06 | J5: =TRIM(A5) -> 23/0082 | K5: =MID(J5,4,1) -> 0 | L5: =IF(K5="9","9_podnik. Réžia",IF(K5="5","5_režijné zákazky",IF(K5="8","8_drobné zákazky",IF(K5="7","7_Vyskum_a_vyvoj","jednicové zákazky")))) -> jednicové zákazky
A6: 23/0082 | B6: Základový rám 1 ks | C6: VP5 | D6: ŽN | E6: Apretúra | F6: 5.5 | G6: 0 | H6: 5.5 | I6: 2026/06 | J6: =TRIM(A6) -> 23/0082 | K6: =MID(J6,4,1) -> 0 | L6: =IF(K6="9","9_podnik. Réžia",IF(K6="5","5_režijné zákazky",IF(K6="8","8_drobné zákazky",IF(K6="7","7_Vyskum_a_vyvoj","jednicové zákazky")))) -> jednicové zákazky
A7: 23/0083 | B7: Základový rám 1 ks | C7: VP2 | D7: JR | E7: Skladanie | F7: 18 | G7: 1.5 | H7: 19.5 | I7: 2026/06 | J7: =TRIM(A7) -> 23/0083 | K7: =MID(J7,4,1) -> 0 | L7: =IF(K7="9","9_podnik. Réžia",IF(K7="5","5_režijné zákazky",IF(K7="8","8_drobné zákazky",IF(K7="7","7_Vyskum_a_vyvoj","jednicové zákazky")))) -> jednicové zákazky
A8: 23/0083 | B8: Základový rám 1 ks | C8: VP2 | D8: JR | E8: Zváranie | F8: 5 | G8: 0 | H8: 5 | I8: 2026/06 | J8: =TRIM(A8) -> 23/0083 | K8: =MID(J8,4,1) -> 0 | L8: =IF(K8="9","9_podnik. Réžia",IF(K8="5","5_režijné zákazky",IF(K8="8","8_drobné zákazky",IF(K8="7","7_Vyskum_a_vyvoj","jednicové zákazky")))) -> jednicové zákazky
A9: 23/0083 | B9: Základový rám 1 ks | C9: VP2 | D9: JR | E9: Zámočník | F9: 16 | G9: 0 | H9: 16 | I9: 2026/06 | J9: =TRIM(A9) -> 23/0083 | K9: =MID(J9,4,1) -> 0 | L9: =IF(K9="9","9_podnik. Réžia",IF(K9="5","5_režijné zákazky",IF(K9="8","8_drobné zákazky",IF(K9="7","7_Vyskum_a_vyvoj","jednicové zákazky")))) -> jednicové zákazky
A10: 23/0083 | B10: Základový rám 1 ks | C10: VP2 | D10: ŽN | E10: Zám. po zvár. | F10: 4 | G10: 0 | H10: 4 | I10: 2026/06 | J10: =TRIM(A10) -> 23/0083 | K10: =MID(J10,4,1) -> 0 | L10: =IF(K10="9","9_podnik. Réžia",IF(K10="5","5_režijné zákazky",IF(K10="8","8_drobné zákazky",IF(K10="7","7_Vyskum_a_vyvoj","jednicové zákazky")))) -> jednicové zákazky
A11: 23/0083 | B11: Základový rám 1 ks | C11: VP5 | D11: JR | E11: Apretúra | F11: 48 | G11: 0 | H11: 48 | I11: 2026/06 | J11: =TRIM(A11) -> 23/0083 | K11: =MID(J11,4,1) -> 0 | L11: =IF(K11="9","9_podnik. Réžia",IF(K11="5","5_režijné zákazky",IF(K11="8","8_drobné zákazky",IF(K11="7","7_Vyskum_a_vyvoj","jednicové zákazky")))) -> jednicové zákazky
A12: 23/0083 | B12: Základový rám 1 ks | C12: VP5 | D12: ŽN | E12: Lakovanie | F12: 8 | G12: 0 | H12: 8 | I12: 2026/06 | J12: =TRIM(A12) -> 23/0083 | K12: =MID(J12,4,1) -> 0 | L12: =IF(K12="9","9_podnik. Réžia",IF(K12="5","5_režijné zákazky",IF(K12="8","8_drobné zákazky",IF(K12="7","7_Vyskum_a_vyvoj","jednicové zákazky")))) -> jednicové zákazky
A13: 23/0084 | B13: Základový rám 1 ks | C13: VP2 | D13: JR | E13: Zámočník | F13: 4 | G13: 0 | H13: 4 | I13: 2026/06 | J13: =TRIM(A13) -> 23/0084 | K13: =MID(J13,4,1) -> 0 | L13: =IF(K13="9","9_podnik. Réžia",IF(K13="5","5_režijné zákazky",IF(K13="8","8_drobné zákazky",IF(K13="7","7_Vyskum_a_vyvoj","jednicové zákazky")))) -> jednicové zákazky
... A342: XX/9999 | B342: Podniková réžia | C342: VP5 | D342: ŽN | E342: Pieskovanie | F342: 46.5 | G342: 0 | H342: 46.5 | I342: 2026/06 | J342: =TRIM(A342) -> XX/9999 | K342: =MID(J342,4,1) -> 9 | L342: =IF(K342="9","9_podnik. Réžia",IF(K342="5","5_režijné zákazky",IF(K342="8","8_drobné zákazky",IF(K342="7","7_Vyskum_a_vyvoj","jednicové zákazky")))) -> 9_podnik. Réžia

Sheet Hárok4
A1: Zákazka | B1: Názov zákazky | C1: Výrobný úsek | D1: Kategória | E1: Stredisko | F1: ZF [hod] | G1: NC [hod] | H1: Spolu [hod] | I1: obdobie | J1: Zakazka_upr | K1: cd_typ_Zákazky | L1: nm_typ_zákazky
A2: XX/9999 | B2: Podniková réžia | C2: VP2 | D2: JR | E2: Zámočník | F2: 6 | G2: 0 | H2: 6 | I2: 2019/11 | J2: XX/9999 | K2: 9 | L2: 9_podnik. Réžia
A3: XX/9999 | B3: Podniková réžia | C3: VP2 | D3: JR | E3: Zváranie | F3: 39 | G3: 0 | H3: 39 | I3: 2019/11 | J3: XX/9999 | K3: 9 | L3: 9_podnik. Réžia
A4: XX/9999 | B4: Podniková réžia | C4: VP2 | D4: JR | E4: Výroba dielcov | F4: 6 | G4: 0 | H4: 6 | I4: 2019/11 | J4: XX/9999 | K4: 9 | L4: 9_podnik. Réžia
A5: XX/9999 | B5: Podniková réžia | C5: VP2 | D5: JR | E5: Skladanie | F5: 21 | G5: 0 | H5: 21 | I5: 2019/11 | J5: XX/9999 | K5: 9 | L5: 9_podnik. Réžia
A6: XX/9999 | B6: Podniková réžia | C6: VP2 | D6: JR | E6: Rovnanie | F6: 6 | G6: 0 | H6: 6 | I6: 2019/11 | J6: XX/9999 | K6: 9 | L6: 9_podnik. Réžia

Sheet 2026_06_sumar
B2: ROZBOR HODÍN ZA MESIAC | F2: =C34 -> 2026/06
B4: Školenia - manuálny vstup
B5: dostupné hneď po prenose dochádzky
B7: =C35 -> JR | C7: =SUM(C8:C13) -> 0
B8: VP1
B9: VP2
B10: VP3V
B11: VP3M
B12: VP4
B13: VP5
B14: VP3T
B17: Odpracované hodiny (A+B+C+školenia+D): | H17: B) režijné zákazky (rr/5xxx)
B18: odvedené + podniková réžia + réžijné zákazky + školenia+VaV
H19: Súčet z Spolu [hod] | I19: Označenia stĺpcov
C20: =C34 -> 2026/06 | I20: 2026/06 | L20: spolu
B21: Označenia riadkov | C21: =C35 -> JR | D21: =E35 -> ŽN+POL | E21: spolu | H21: Označenia riadkov | I21: JR | J21: RŽ | K21: ŽN+POL
B22: Odracované hod. | C22: =SUM(C23:C29) -> 8328 | D22: =SUM(D23:D29) -> 7591.5 | E22: =D22+C22 -> 15919.5 | H22: 5_režijné zákazky | I22: 20.5 | L22: 20.5
B23: VP1 | C23: =SUM(C37:D37,C45:D45)+I23+I37+C8+C53+D53 -> 3081.25 | D23: =SUM(E37,E45)+K23+J37+D8+E53 -> 5360 | E23: =D23+C23 -> 8441.25 | H23: VP1 | I23: 11.5 | L23: 11.5
B24: VP2 | C24: =SUM(C38:D38,C46:D46)+I24+I38+C9+C54 -> 2026.5 | D24: =SUM(E38,E46)+K24+J38+D9+E54 -> 831.5 | E24: =D24+C24 -> 2858 | H24: VP2 | I24: 6 | L24: 6
B25: VP3V | C25: =SUM(C39:D39,C47:D47)+I25+I39+C10+C55 -> 1170 | D25: =SUM(E39,E47)+K25+J39+D10+E55 -> 0 | E25: =D25+C25 -> 1170 | H25: VP3V
B26: VP3M | C26: =SUM(C40:D40,C48:D48)+I26+I40+C11+C56 -> 1145.75 | D26: =SUM(E40,E48)+K26+J40+D11+E56 -> 125 | E26: =D26+C26 -> 1270.75 | H26: VP3M | I26: 3 | L26: 3
B27: VP4 | C27: =SUM(C41:D41,C49:D49)+I27+I41+C12+C57 -> 0 | D27: =SUM(E41,E49)+K27+J41+D12+E57 -> 0 | E27: =D27+C27 -> 0 | H27: VP4
B28: VP5 | C28: =SUM(C42:D42,C50:D50)+I28+I42+C13+C58 -> 646.5 | D28: =SUM(E42,E50)+K28+J42+D13+E58 -> 1101 | E28: =D28+C28 -> 1747.5 | H28: VP5
B29: VP3Tlmače | C29: =SUM(C43:D43,C51:D51)+I29+I43+C14+C59 -> 258 | D29: =SUM(E43,E51)+K29+J43+D14+E59 -> 174 | E29: =D29+C29 -> 432 | H29: VP3T
B31: A) Odvedené hodiny: externé zákazky + drobné zákazky+výskum a vývoj | H31: C) Podniková réžia (rr/9xxx)
B33: Súčet z Spolu [hod] | C33: Označenia stĺpcov | H33: Súčet z Spolu [hod] | I33: Označenia stĺpcov
C34: 2026/06 | F34: spolu | I34: 2026/06 | K34: spolu
B35: Označenia riadkov | C35: JR | D35: RŽ | E35: ŽN+POL | H35: Označenia riadkov | I35: JR | J35: ŽN+POL | M35: PR+školenia | N35: réžia celkom
B36: jednicové zákazky | C36: 8070.5 | E36: 7545 | F36: 15615.5 | H36: 9_podnik. Réžia | I36: 212.5 | J36: 46.5 | K36: 259 | M36: =K36+C7 -> 259 | N36: =SUM(N37:N43) -> 279.5
B37: VP1 | C37: 2986.25 | E37: 5360 | F37: 8346.25 | H37: VP1 | I37: 69 | K37: 69 | M37: =K37+C8 -> 69 | N37: =M37+GETPIVOTDATA("Spolu [hod]",$H$19,"Výrobný úsek","VP1 ","obdobie","2026/06","nm_typ_zákazky","5_režijné zákazky") -> 80.5
B38: VP2 | C38: 1976.5 | E38: 831.5 | F38: 2808 | H38: VP2 | I38: 34 | K38: 34 | M38: =K38+C9 -> 34 | N38: =M38+GETPIVOTDATA("Spolu [hod]",$H$19,"Výrobný úsek","VP2 ","obdobie","2026/06","nm_typ_zákazky","5_režijné zákazky") -> 40
B39: VP3V | C39: 1093.5 | F39: 1093.5 | H39: VP3V | I39: 76.5 | K39: 76.5 | M39: =K39+C10 -> 76.5 | N39: =M39+GETPIVOTDATA("Spolu [hod]",$H$19,"Výrobný úsek","VP3V ","obdobie","2026/06","nm_typ_zákazky","5_režijné zákazky") -> 76.5
B40: VP3M | C40: 1126.75 | E40: 125 | F40: 1251.75 | H40: VP3M | I40: 16 | K40: 16 | M40: =K40+C11 -> 16 | N40: =M40+GETPIVOTDATA("Spolu [hod]",$H$19,"Výrobný úsek","VP3M ","obdobie","2026/06","nm_typ_zákazky","5_režijné zákazky") -> 19
B41: VP4 | H41: VP4 | M41: =K41+C12 -> 0 | N41: =M41+GETPIVOTDATA("Spolu [hod]",$H$19,"Výrobný úsek","VP4 ","obdobie","2026/06","nm_typ_zákazky","5_režijné zákazky") -> 0
B42: VP5 | C42: 629.5 | E42: 1054.5 | F42: 1684 | H42: VP5 | I42: 17 | J42: 46.5 | K42: 63.5 | M42: =K42+C13 -> 63.5 | N42: =M42+GETPIVOTDATA("Spolu [hod]",$H$19,"Výrobný úsek","VP5 ","obdobie","2026/06","nm_typ_zákazky","5_režijné zákazky") -> 63.5
B43: VP3T | C43: 258 | E43: 174 | F43: 432 | H43: VP3T | M43: =K43+C14 -> 0 | N43: 0
B44: 8_drobné zákazky | C44: 24.5 | F44: 24.5
B45: VP1 | C45: 14.5 | F45: 14.5
B46: VP2 | C46: 10 | F46: 10
B47: VP3V
...

Sheet KUMULÁCIE
B1: Prehľad odpracovaných a odvedených hodín za rok 2026 podľa VP | I1: kopírovať do časového fondu
C3: ='2026_06_sumar'!C34 -> 2026/06
B5: Odvedené hod.- JZ,drobné zák. | C5: =SUM(C6:C11) -> 15640
B6: • VP1 | C6: =C14-C61-C53 -> 8360.75
B7: • VP2 | C7: =C15-C62-C54+1 -> 2818 | D7: 2298
B8: • VP3V | C8: =C16-C63-C55 -> 1093.5 | D8: =SUM(C8:C9) -> 2345.25
B9: • VP3M | C9: =C17-C64-C56 -> 1251.75
B10: • VP3T | C10: =C18-C65-C57 -> 432
B11: • VP5 | C11: =C19-C66-C58 -> 1684
B13: Odpracované hodiny spolu | C13: =SUM(C14:C19)+1 -> 15919.5
B14: • VP1 | C14: =C22+C30 -> 8441.25
B15: • VP2 | C15: =C23+C31 -> 2857
B16: • VP3V | C16: =C24+C32 -> 1170 | D16: =SUM(C16:C17) -> 2440.75
B17: • VP3M | C17: =C25+C33 -> 1270.75
B18: • VP3T | C18: =C26+C34 -> 432
B19: • VP5 | C19: =C27+C35 -> 1747.5 | D19: =C13-C18 -> 15487.5
B21: Z toho zamestnanci spolu | C21: =SUM(C22:C27) -> 8328
B22: • VP1 | C22: ='2026_06_sumar'!C23 -> 3081.25
B23: • VP2 | C23: ='2026_06_sumar'!C24 -> 2026.5
B24: • VP3V | C24: ='2026_06_sumar'!C25 -> 1170
B25: • VP3M | C25: ='2026_06_sumar'!C26 -> 1145.75
B26: • VP3T | C26: ='2026_06_sumar'!C29 -> 258
B27: • VP5 | C27: ='2026_06_sumar'!C28 -> 646.5
B29: Z toho živnostníci spolu | C29: =SUM(C30:C35)+1 -> 7591.5
B30: • VP1 | C30: ='2026_06_sumar'!D23 -> 5360
B31: • VP2 | C31: ='2026_06_sumar'!D24-1 -> 830.5
B32: • VP3V | C32: ='2026_06_sumar'!D25 -> 0
B33: • VP3M | C33: ='2026_06_sumar'!D26 -> 125
B34: • VP3T | C34: ='2026_06_sumar'!D29 -> 174
B35: • VP5 | C35: ='2026_06_sumar'!D28 -> 1101
B37: Z odprac.hodín spolu (16; 17/7...) | C37: =SUM(C38:C43) -> 0
B38: • VP1 | C38: ='2026_06_sumar'!C53 -> 0
B39: • VP2 | C39: ='2026_06_sumar'!C54 -> 0
B40: • VP3V | C40: 0
B41: • VP3M | C41: ='2026_06_sumar'!C56 -> 0
B42: • VP3T | C42: ='2026_06_sumar'!C59 -> 0
B43: • VP5 | C43: ='2026_06_sumar'!C58 -> 0
B44: Z odprac.hodín spolu xx/56xx | C44: =SUM(C45:C50) -> 0 | D44: !!!! | E44: pozor ZMENA - všetky réžijné zákazky začínajúce za lomítkom / 56xx
B45: • VP1 | C45: ='2026_06_sumar'!M101 -> 0
B46: • VP2 | C46: ='2026_06_sumar'!M102 -> 0
...

Sheet Hárok3
A1: Zákazka | B1: Názov zákazky | C1: Výrobný úsek | D1: Kategória | E1: Stredisko | F1: ZF [hod] | G1: NC [hod] | H1: Spolu [hod] | I1: obdobie | J1: Zakazka_upr | K1: cd_typ_Zákazky | L1: nm_typ_zákazky
A2: 19/8097 | B2: ToMich_3x_Výpalky | C2: VP1 | D2: JR | E2: Pálenie | F2: 1 | G2: 0 | H2: 1 | I2: 2019/11 | J2: 19/8097 | K2: 8 | L2: 8_drobné zákazky
A3: 18/0093 | B3: VEKOMA_minterain polsko | C3: VP1 | D3: JR | E3: Brúsenie | F3: 91 | G3: 9 | H3: 100 | I3: 2019/11 | J3: 18/0093 | K3: 0 | L3: jednicové zákazky
A4: 18/0093 | B4: VEKOMA_minterain polsko | C4: VP1 | D4: JR | E4: Pálenie | F4: 10 | G4: 14.25 | H4: 24.25 | I4: 2019/11 | J4: 18/0093 | K4: 0 | L4: jednicové zákazky
A5: 18/0093 | B5: VEKOMA_minterain polsko | C5: VP1 | D5: JR | E5: Rezanie | F5: 21.5 | G5: 1.5 | H5: 23 | I5: 2019/11 | J5: 18/0093 | K5: 0 | L5: jednicové zákazky
A6: 18/0093 | B6: VEKOMA_minterain polsko | C6: VP1 | D6: JR | E6: Skladanie | F6: 112 | G6: 16 | H6: 128 | I6: 2019/11 | J6: 18/0093 | K6: 0 | L6: jednicové zákazky
A7: 18/0093 | B7: VEKOMA_minterain polsko | C7: VP1 | D7: JR | E7: Strihanie | F7: 5 | G7: 0 | H7: 5 | I7: 2019/11 | J7: 18/0093 | K7: 0 | L7: jednicové zákazky
A8: 18/0093 | B8: VEKOMA_minterain polsko | C8: VP1 | D8: JR | E8: Zváranie | F8: 27.5 | G8: 0 | H8: 27.5 | I8: 2019/11 | J8: 18/0093 | K8: 0 | L8: jednicové zákazky
A9: 19/8094 | B9: ToMich_10x_Pálenie+materiál | C9: VP1 | D9: JR | E9: Pálenie | F9: 1 | G9: 0 | H9: 1 | I9: 2019/11 | J9: 19/8094 | K9: 8 | L9: 8_drobné zákazky
A10: 19/0165 | B10: VEM_1x_Fundamentrahmen | C10: VP1 | D10: JR | E10: Strihanie | F10: 3.5 | G10: 0 | H10: 3.5 | I10: 2019/11 | J10: 19/0165 | K10: 0 | L10: jednicové zákazky
A11: 19/0165 | B11: VEM_1x_Fundamentrahmen | C11: VP1 | D11: JR | E11: Pálenie | F11: 3 | G11: 0 | H11: 3 | I11: 2019/11 | J11: 19/0165 | K11: 0 | L11: jednicové zákazky
A12: 19/0165 | B12: VEM_1x_Fundamentrahmen | C12: VP1 | D12: JR | E12: Brúsenie | F12: 4 | G12: 0 | H12: 4 | I12: 2019/11 | J12: 19/0165 | K12: 0 | L12: jednicové zákazky
A13: 19/0164 | B13: VEM_2x_Gehäuse | C13: VP1 | D13: JR | E13: Strihanie | F13: 10 | G13: 0 | H13: 10 | I13: 2019/11 | J13: 19/0164 | K13: 0 | L13: jednicové zákazky
... A114: 19/0055 | B114: VEKOMA_1x_STC-Stanica | C114: VP1 | D114: JR | E114: Rezanie | F114: 3 | G114: 3 | H114: 6 | I114: 2019/11 | J114: 19/0055 | K114: 0 | L114: jednicové zákazky

Sheet Hárok5
A1: Zákazka | B1: Názov zákazky | C1: Výrobný úsek | D1: Kategória | E1: Stredisko | F1: ZF [hod] | G1: NC [hod] | H1: Spolu [hod] | I1: obdobie | J1: Zakazka_upr | K1: cd_typ_Zákazky | L1: nm_typ_zákazky
A2: 22/8046 | B2: Strihanie plechu 2 ks | C2: VP1 | D2: JR | E2: Brúsenie | F2: 0.5 | G2: 0 | H2: 0.5 | I2: 2022/06 | J2: 22/8046 | K2: 8 | L2: 8_drobné zákazky
A3: 21/0121 | B3: 3D dráha Family Boomerang | C3: VP1 | D3: JR | E3: Brúsenie | F3: 8 | G3: 0 | H3: 8 | I3: 2022/06 | J3: 21/0121 | K3: 0 | L3: jednicové zákazky
A4: 21/0121 | B4: 3D dráha Family Boomerang | C4: VP1 | D4: JR | E4: Ostatné | F4: 16 | G4: 0 | H4: 16 | I4: 2022/06 | J4: 21/0121 | K4: 0 | L4: jednicové zákazky
A5: 22/8042 | B5: Rezanie | C5: VP1 | D5: JR | E5: Brúsenie | F5: 1 | G5: 0 | H5: 1 | I5: 2022/06 | J5: 22/8042 | K5: 8 | L5: 8_drobné zákazky
A6: 21/0140 | B6: Stĺpy pre Slide Wheel | C6: VP1 | D6: JR | E6: Brúsenie | F6: 27.5 | G6: 2 | H6: 29.5 | I6: 2022/06 | J6: 21/0140 | K6: 0 | L6: jednicové zákazky
A7: 21/0140 | B7: Stĺpy pre Slide Wheel | C7: VP1 | D7: JR | E7: Pálenie | F7: 22 | G7: 0 | H7: 22 | I7: 2022/06 | J7: 21/0140 | K7: 0 | L7: jednicové zákazky
A8: 21/0140 | B8: Stĺpy pre Slide Wheel | C8: VP1 | D8: JR | E8: Rezanie | F8: 20 | G8: 0 | H8: 20 | I8: 2022/06 | J8: 21/0140 | K8: 0 | L8: jednicové zákazky
A9: 22/8035 | B9: Skruženie profili I300 1 ks | C9: VP1 | D9: JR | E9: Ohýbanie rúr | F9: 22.5 | G9: 0 | H9: 22.5 | I9: 2022/06 | J9: 22/8035 | K9: 8 | L9: 8_drobné zákazky
A10: 22/8035 | B10: Skruženie profili I300 1 ks | C10: VP1 | D10: JR | E10: Brúsenie | F10: 16 | G10: 0 | H10: 16 | I10: 2022/06 | J10: 22/8035 | K10: 8 | L10: 8_drobné zákazky
A11: 21/0200 | B11: 2D SFC Phoenix Vodante | C11: VP1 | D11: JR | E11: Brúsenie | F11: 24 | G11: 0 | H11: 24 | I11: 2022/06 | J11: 21/0200 | K11: 0 | L11: jednicové zákazky
A12: 22/0121 | B12: Abdeckung | C12: VP1 | D12: JR | E12: Rezanie | F12: 5 | G12: 0 | H12: 5 | I12: 2022/06 | J12: 22/0121 | K12: 0 | L12: jednicové zákazky
A13: 22/0121 | B13: Abdeckung | C13: VP1 | D13: JR | E13: Brúsenie | F13: 14 | G13: 0 | H13: 14 | I13: 2022/06 | J13: 22/0121 | K13: 0 | L13: jednicové zákazky
... A233: 22/0078 | B233: Dráha 3D-Tilt Coaster-Energylandia | C233: VP5 | D233: JR | E233: Pieskov.dielce | F233: 16 | G233: 2.5 | H233: 18.5 | I233: 2022/06 | J233: 22/0078 | K233: 0 | L233: jednicové zákazky

Sheet 2026_06_rozpočet_RN_sumar
D4: 2026/06 Režijné Náklady spolu | I4: 557403
D5: a) Zúčtovanie RN do zákaziek na základe odvedených hodín (JZ+drobn.zák.) | I5: 360926.25
D6: b) Zúčtovanie RN do zákaziek na základe odvedených hodín 25/5605 | I6: 0
D7: c) Zúčtovanie RN do zákaziek na základe odvedených hodín 25/5606 | I7: 0
D8: d) Zúčtovanie RN do zákaziek na základe odvedených hodín 25/5608 | I8: 0
D9: e)Zúčtovanie RN ako internej prepravy a manipulácie (JZ) | I9: 23344
D10: f)Zúčtovanie RN ako internej prepravy a manipulácie 25/5608 | I10: 0
D12: Zúčtovaná réžia spolu (a): | I12: =I5+I6+I9+I10+I7 -> 384270.25
D13: Nerozpustená réžia | I13: =I4-I12 -> 173132.75
D14: c) Výpočet réžie - pre neodvedené hodiny podľa časového fondu (plánu) | I14: =-I81 -> 92886.375
D15: d)Výskumno vývojové zákazky | I15: 0
D16: interná preprava (N strediska Doprava) | I16: 10506 | J16: =I13-I14-I15-I16 -> 69740.375
D17: e)Prekročené RN oproti plánu | I17: 0
D18: f) Odstup. Odchodné | I18: 0
I19: =I13-I14-I15-I17-I18 -> 80246.375
D21: A) Rozpustenie Režijných nákladov do zákaziek na základe odvedených hodín
G22: Fréza + horizontka + Karusel + lakovanie + Pieskovanie
G23: obdobie | H23: (Všetko)
C24: Jednicové zákazky+Drobné z. | D24: obdobie | E24: (Všetko) | G24: nm_typ_zákazky | H24: (Viacero položiek)
D25: nm_typ_zákazky | E25: (Viacero položiek) | G25: Stredisko | H25: (Viacero položiek) | L25: sadzba VO
K26: Zákl. sadzba | L26: F+H+K+P+L
D27: Označenia riadkov | E27: Súčet z Spolu [hod] | G27: Označenia riadkov | H27: Súčet z Spolu [hod] | K27: 18 | L27: 25 | M27: Spolu
D28: JR | E28: 8095 | G28: JR | H28: 1834.25 | J28: =D28 -> JR | K28: =$K$27*E28 -> 145710 | L28: =H28*$L$27 -> 45856.25 | M28: =L28+K28 -> 191566.25
D29: VP1 | E29: 3000.75 | G29: VP1 | J29: =D29 -> VP1 | K29: =$K$27*E29 -> 54013.5 | L29: =H29*$L$27 -> 0 | M29: =L29+K29 -> 54013.5 | O29: =J29 -> VP1 | P29: =M29+M36+M43 -> 54013.5
D30: VP2 | E30: 1986.5 | G30: VP2 | J30: =D30 -> VP2 | K30: =$K$27*E30 -> 35757 | L30: =H30*$L$27 -> 0 | M30: =L30+K30 -> 35757 | O30: =J30 -> VP2 | P30: =M30+M37+M44 -> 205117
D31: VP3V | E31: 1093.5 | G31: VP3V | H31: 913 | J31: =D31 -> VP3V | K31: =$K$27*E31 -> 19683 | L31: =H31*$L$27 -> 22825 | M31: =L31+K31 -> 42508 | O31: =J31 -> VP3V | P31: =M31+M38+M45 -> 138988
D32: VP3M | E32: 1126.75 | G32: VP3M | H32: 783.25 | J32: =D32 -> VP3M | K32: =$K$27*E32 -> 20281.5 | L32: =H32*$L$27 -> 19581.25 | M32: =L32+K32 -> 39862.75 | O32: =J32 -> VP3M | P32: =M32+M39+M46 -> 54829.75
D33: VP4 | G33: VP4 | J33: =D33 -> VP4 | K33: =$K$27*E33 -> 0 | L33: =H33*$L$27 -> 0 | M33: =L33+K33 -> 0 | O33: =J33 -> VP4 | P33: =M33+M40+M47 -> 0
D34: VP5 | E34: 629.5 | G34: VP5 | H34: 138 | J34: =D34 -> VP5 | K34: =$K$27*E34 -> 11331 | L34: =H34*$L$27 -> 3450 | M34: =L34+K34 -> 14781 | O34: =J34 -> VP5 | P34: =M34+M41+M48 -> 20156
D35: VP3T | E35: 258 | G35: VP3T | J35: =D35 -> VP3T | K35: =$K$27*E35 -> 4644 | L35: =H35*$L$27 -> 0 | M35: =L35+K35 -> 4644 | O35: VP3V-Tlmače | P35: =#REF! -> #REF!
D36: RŽ | G36: RŽ | J36: =D36 -> RŽ | K36: =$K$27*E36 -> 0 | L36: =H36*$L$27 -> 0 | M36: =L36+K36 -> 0
D37: VP1 | G37: VP1 | J37: =D37 -> VP1 | K37: =$K$27*E37 -> 0 | L37: =H37*$L$27 -> 0 | M37: =L37+K37 -> 0
D38: VP2 | G38: VP2 | J38: =D38 -> VP2 | K38: =$K$27*E38 -> 0 | L38: =H38*$L$27 -> 0 | M38: =L38+K38 -> 0
D39: VP3V | G39: VP3V | J39: =D39 -> VP3V | K39: =$K$27*E39 -> 0 | L39: =H39*$L$27 -> 0 | M39: =L39+K39 -> 0
D40: VP3M | G40: VP3M | J40: =D40 -> VP3M | K40: =$K$27*E40 -> 0 | L40: =H40*$L$27 -> 0 | M40: =L40+K40 -> 0
D41: VP4 | G41: VP4 | J41: =D41 -> VP4 | K41: =$K$27*E41 -> 0 | L41: =H41*$L$27 -> 0 | M41: =L41+K41 -> 0
D42: VP5 | G42: VP5 | J42: =D42 -> VP5 | K42: =$K$27*E42 -> 0 | L42: =H42*$L$27 -> 0 | M42: =L42+K42 -> 0
D43: VP3T | G43: VP3T | J43: =D43 -> VP3T | K43: =$K$27*E43 -> 0 | L43: =H43*$L$27 -> 0 | M43: =L43+K43 -> 0
D44: ŽN+POL | E44: 7545 | G44: ŽN+POL | H44: 1342 | J44: =D44 -> ŽN+POL | K44: =$K$27*E44 -> 135810 | L44: =H44*$L$27 -> 33550 | M44: =L44+K44 -> 169360
D45: VP1 | E45: 5360 | G45: VP1 | J45: =D45 -> VP1 | K45: =$K$27*E45 -> 96480 | L45: =H45*$L$27 -> 0 | M45: =L45+K45 -> 96480
...

Sheet 2026_06_rozpočet_RN_zakazky_A
B2: ='2026_06_rozpočet_RN_sumar'!D5 -> a) Zúčtovanie RN do zákaziek na základe odvedených hodín (JZ+drobn.zák.) | M2: rozúčtovanie odvedených hodín na zákazky | V2: doučtovanie vyššej sadzby na zákazky s velkým obrábaním F+H+K a zakazky na pieskovanie + lakovanie
B4: =ROUND(SUM(G11:G91),2) -> 360926.25 | C4: =B4='2026_06_rozpočet_RN_sumar'!I5 -> TRUE
M5: obdobie | N5: (Všetko) | P5: =P10 -> JR | Q5: =Q10 -> RŽ | R5: =R10 -> ŽN+POL | S5: =S10 -> Spolu | V5: obdobie | W5: (Všetko) | Y5: =Y10 -> JR | Z5: =Z10 -> RŽ | AA5: =AA10 -> ŽN+POL | AB5: =AB10 -> Spolu
M6: Výrobný úsek | N6: (Viacero položiek) | O6: JR+ŽN z úkolu | P6: =SUM(P11:P1048576) -> 8095 | Q6: =SUM(Q11:Q1048576) -> 0 | R6: =SUM(R11:R1048576) -> 7545 | S6: =SUM(S11:S1048576) -> 15640 | V6: Výrobný úsek | W6: (Viacero položiek) | X6: JR+ŽN z úkolu | Y6: =SUM(Y11:Y1048576) -> 1834.25 | Z6: =SUM(Z11:Z1048576) -> 0 | AA6: =SUM(AA11:AA1048576) -> 1342 | AB6: =SUM(AB11:AB1048576) -> 3176.25
M7: Stredisko | N7: (Všetko) | V7: Stredisko | W7: (Viacero položiek)
C9: JR | D9: JR | E9: ZN | F9: ZN | I9: ABRA | M9: Súčet z Spolu [hod] | P9: Kategória2 | V9: Súčet z Spolu [hod] | Y9: Kategória2
C10: 18 | D10: 25 | E10: 18 | F10: 25 | G10: Spolu | I10: douct. RN na zakazku | M10: nm_typ_zákazky | N10: Zakazka_upr | O10: Názov zákazky | P10: JR | Q10: RŽ | R10: ŽN+POL | S10: Spolu | V10: nm_typ_zákazky | W10: Zakazka_upr | X10: Názov zákazky | Y10: JR | Z10: RŽ | AA10: ŽN+POL | AB10: Spolu
B11: =N11 -> 23/0082 | C11: =$C$10*(P11+Q11) -> 1080 | D11: =IFERROR(((VLOOKUP(B11,$W$11:$AB$112,3,0)+VLOOKUP(B11,$W$11:$AB$112,4,0))*$D$10),0) -> 200 | E11: =R11*$E$10 -> 207 | F11: =IFERROR(((VLOOKUP(B11,$W$11:$AB$112,5,0))*$F$10),0) -> 0 | G11: =SUM(C11:F11) -> 1487 | I11: =SUM(D11:F11) -> 407 | M11: jednicové zákazky2 | N11: 23/0082 | O11: Základový rám 1 ks | P11: 60 | R11: 11.5 | S11: 71.5 | V11: jednicové zákazky2 | W11: 23/0082 | X11: Základový rám 1 ks | Y11: 8 | AB11: 8
B12: =N12 -> 23/0083 | C12: =$C$10*(P12+Q12) -> 1593 | D12: =IFERROR(((VLOOKUP(B12,$W$11:$AB$112,3,0)+VLOOKUP(B12,$W$11:$AB$112,4,0))*$D$10),0) -> 0 | E12: =R12*$E$10 -> 216 | F12: =IFERROR(((VLOOKUP(B12,$W$11:$AB$112,5,0))*$F$10),0) -> 200 | G12: =SUM(C12:F12) -> 2009 | I12: =SUM(D12:F12) -> 416 | M12: jednicové zákazky2 | N12: 23/0083 | O12: Základový rám 1 ks | P12: 88.5 | R12: 12 | S12: 100.5 | V12: jednicové zákazky2 | W12: 23/0083 | X12: Základový rám 1 ks | AA12: 8 | AB12: 8
B13: =N13 -> 23/0084 | C13: =$C$10*(P13+Q13) -> 360 | D13: =IFERROR(((VLOOKUP(B13,$W$11:$AB$112,3,0)+VLOOKUP(B13,$W$11:$AB$112,4,0))*$D$10),0) -> 400 | E13: =R13*$E$10 -> 144 | F13: =IFERROR(((VLOOKUP(B13,$W$11:$AB$112,5,0))*$F$10),0) -> 0 | G13: =SUM(C13:F13) -> 904 | I13: =SUM(D13:F13) -> 544 | M13: jednicové zákazky2 | N13: 23/0084 | O13: Základový rám 1 ks | P13: 20 | R13: 8 | S13: 28 | V13: jednicové zákazky2 | W13: 23/0084 | X13: Základový rám 1 ks | Y13: 16 | AB13: 16
B14: =N14 -> 25/0055 | C14: =$C$10*(P14+Q14) -> 3816 | D14: =IFERROR(((VLOOKUP(B14,$W$11:$AB$112,3,0)+VLOOKUP(B14,$W$11:$AB$112,4,0))*$D$10),0) -> 500 | E14: =R14*$E$10 -> 9576 | F14: =IFERROR(((VLOOKUP(B14,$W$11:$AB$112,5,0))*$F$10),0) -> 4512.5 | G14: =SUM(C14:F14) -> 18404.5 | I14: =SUM(D14:F14) -> 14588.5 | M14: jednicové zákazky2 | N14: 25/0055 | O14: 3D Dráha | P14: 212 | R14: 532 | S14: 744 | V14: jednicové zákazky2 | W14: 25/0055 | X14: 3D Dráha | Y14: 20 | AA14: 180.5 | AB14: 200.5
B15: =N15 -> 25/1002 | C15: =$C$10*(P15+Q15) -> 3123 | D15: =IFERROR(((VLOOKUP(B15,$W$11:$AB$112,3,0)+VLOOKUP(B15,$W$11:$AB$112,4,0))*$D$10),0) -> 4337.5 | E15: =R15*$E$10 -> 3343.5 | F15: =IFERROR(((VLOOKUP(B15,$W$11:$AB$112,5,0))*$F$10),0) -> 1943.75 | G15: =SUM(C15:F15) -> 12747.75 | I15: =SUM(D15:F15) -> 9624.75 | M15: jednicové zákazky2 | N15: 25/1002 | O15: SWITCH 9ks | P15: 173.5 | R15: 185.75 | S15: 359.25 | V15: jednicové zákazky2 | W15: 25/1002 | X15: SWITCH 9ks | Y15: 173.5 | AA15: 77.75 | AB15: 251.25
B16: =N16 -> 25/0095 | C16: =$C$10*(P16+Q16) -> 9751.5 | D16: =IFERROR(((VLOOKUP(B16,$W$11:$AB$112,3,0)+VLOOKUP(B16,$W$11:$AB$112,4,0))*$D$10),0) -> 1443.75 | E16: =R16*$E$10 -> 12451.5 | F16: =IFERROR(((VLOOKUP(B16,$W$11:$AB$112,5,0))*$F$10),0) -> 0 | G16: =SUM(C16:F16) -> 23646.75 | I16: =SUM(D16:F16) -> 13895.25 | M16: jednicové zákazky2 | N16: 25/0095 | O16: 3D DRÁHA - FBCD Karls Erlebnisdorf | P16: 541.75 | R16: 691.75 | S16: 1233.5 | V16: jednicové zákazky2 | W16: 25/0095 | X16: 3D DRÁHA - FBCD Karls Erlebnisdorf | Y16: 57.75 | AB16: 57.75
B17: =N17 -> 25/1001 | C17: =$C$10*(P17+Q17) -> 3933 | D17: =IFERROR(((VLOOKUP(B17,$W$11:$AB$112,3,0)+VLOOKUP(B17,$W$11:$AB$112,4,0))*$D$10),0) -> 1462.5 | E17: =R17*$E$10 -> 15363 | F17: =IFERROR(((VLOOKUP(B17,$W$11:$AB$112,5,0))*$F$10),0) -> 3475 | G17: =SUM(C17:F17) -> 24233.5 | I17: =SUM(D17:F17) -> 20300.5 | M17: jednicové zákazky2 | N17: 25/1001 | O17: 3D Dráha 68 ks | P17: 218.5 | R17: 853.5 | S17: 1072 | V17: jednicové zákazky2 | W17: 25/1001 | X17: 3D Dráha 68 ks | Y17: 58.5 | AA17: 139 | AB17: 197.5
B18: =N18 -> 25/1003 | C18: =$C$10*(P18+Q18) -> 576 | D18: =IFERROR(((VLOOKUP(B18,$W$11:$AB$112,3,0)+VLOOKUP(B18,$W$11:$AB$112,4,0))*$D$10),0) -> 0 | E18: =R18*$E$10 -> 756 | F18: =IFERROR(((VLOOKUP(B18,$W$11:$AB$112,5,0))*$F$10),0) -> 1050 | G18: =SUM(C18:F18) -> 2382 | I18: =SUM(D18:F18) -> 1806 | M18: jednicové zákazky2 | N18: 25/1003 | O18: 2D ku SWITCH | P18: 32 | R18: 42 | S18: 74 | V18: jednicové zákazky2 | W18: 25/1003 | X18: 2D ku SWITCH | AA18: 42 | AB18: 42
B19: =N19 -> 25/0109 | C19: =$C$10*(P19+Q19) -> 1818 | D19: =IFERROR(((VLOOKUP(B19,$W$11:$AB$112,3,0)+VLOOKUP(B19,$W$11:$AB$112,4,0))*$D$10),0) -> 387.5 | E19: =R19*$E$10 -> 1831.5 | F19: =IFERROR(((VLOOKUP(B19,$W$11:$AB$112,5,0))*$F$10),0) -> 18.75 | G19: =SUM(C19:F19) -> 4055.75 | I19: =SUM(D19:F19) -> 2237.75 | M19: jednicové zákazky2 | N19: 25/0109 | O19: 3D Dráha - SF Fiesta Texas | P19: 101 | R19: 101.75 | S19: 202.75 | V19: jednicové zákazky2 | W19: 25/0109 | X19: 3D Dráha - SF Fiesta Texas | Y19: 15.5 | AA19: 0.75 | AB19: 16.25
B20: =N20 -> 25/0115 | C20: =$C$10*(P20+Q20) -> 279 | D20: =IFERROR(((VLOOKUP(B20,$W$11:$AB$112,3,0)+VLOOKUP(B20,$W$11:$AB$112,4,0))*$D$10),0) -> 0 | E20: =R20*$E$10 -> 693 | F20: =IFERROR(((VLOOKUP(B20,$W$11:$AB$112,5,0))*$F$10),0) -> 962.5 | G20: =SUM(C20:F20) -> 1934.5 | I20: =SUM(D20:F20) -> 1655.5 | M20: jednicové zákazky2 | N20: 25/0115 | O20: Kostra statora DAX7-290ERJT 3 ks | P20: 15.5 | R20: 38.5 | S20: 54 | V20: jednicové zákazky2 | W20: 25/0115 | X20: Kostra statora DAX7-290ERJT 3 ks | AA20: 38.5 | AB20: 38.5
B21: =N21 -> 25/0122 | C21: =$C$10*(P21+Q21) -> 144 | D21: =IFERROR(((VLOOKUP(B21,$W$11:$AB$112,3,0)+VLOOKUP(B21,$W$11:$AB$112,4,0))*$D$10),0) -> 0 | E21: =R21*$E$10 -> 0 | F21: =IFERROR(((VLOOKUP(B21,$W$11:$AB$112,5,0))*$F$10),0) -> 0 | G21: =SUM(C21:F21) -> 144 | I21: =SUM(D21:F21) -> 0 | M21: jednicové zákazky2 | N21: 25/0122 | O21: Kostra statora BDAX7-168ER 3 ks | P21: 8 | S21: 8 | V21: jednicové zákazky2 | W21: 25/1004 | X21: 2D SHOW | Y21: 101 | AB21: 101
B22: =N22 -> 25/0133 | C22: =$C$10*(P22+Q22) -> 144 | D22: =IFERROR(((VLOOKUP(B22,$W$11:$AB$112,3,0)+VLOOKUP(B22,$W$11:$AB$112,4,0))*$D$10),0) -> 0 | E22: =R22*$E$10 -> 0 | F22: =IFERROR(((VLOOKUP(B22,$W$11:$AB$112,5,0))*$F$10),0) -> 0 | G22: =SUM(C22:F22) -> 144 | I22: =SUM(D22:F22) -> 0 | M22: jednicové zákazky2 | N22: 25/0133 | O22: Kostra statora DAX7-145ER 2 ks | P22: 8 | S22: 8 | V22: jednicové zákazky2 | W22: 25/0136 | X22: Kostra statora DAX7-290ERJT 7 ks | Y22: 55.5 | AA22: 95.5 | AB22: 151
B23: =N23 -> 25/1004 | C23: =$C$10*(P23+Q23) -> 2214 | D23: =IFERROR(((VLOOKUP(B23,$W$11:$AB$112,3,0)+VLOOKUP(B23,$W$11:$AB$112,4,0))*$D$10),0) -> 2525 | E23: =R23*$E$10 -> 135 | F23: =IFERROR(((VLOOKUP(B23,$W$11:$AB$112,5,0))*$F$10),0) -> 0 | G23: =SUM(C23:F23) -> 4874 | I23: =SUM(D23:F23) -> 2660 | M23: jednicové zákazky2 | N23: 25/1004 | O23: 2D SHOW | P23: 123 | R23: 7.5 | S23: 130.5 | V23: jednicové zákazky2 | W23: 25/1005 | X23: SWITCH 1 segment | Y23: 57.5 | AB23: 57.5
B24: =N24 -> 25/0087 | C24: =$C$10*(P24+Q24) -> 765 | D24: =IFERROR(((VLOOKUP(B24,$W$11:$AB$112,3,0)+VLOOKUP(B24,$W$11:$AB$112,4,0))*$D$10),0) -> 0 | E24: =R24*$E$10 -> 3717 | F24: =IFERROR(((VLOOKUP(B24,$W$11:$AB$112,5,0))*$F$10),0) -> 0 | G24: =SUM(C24:F24) -> 4482 | I24: =SUM(D24:F24) -> 3717 | M24: jednicové zákazky2 | N24: 25/0087 | O24: SWITCH 1 | P24: 42.5 | R24: 206.5 | S24: 249 | V24: jednicové zákazky2 | W24: 26/0004 | X24: Track | Y24: 115 | AA24: 156.25 | AB24: 271.25
B25: =N25 -> 25/0136 | C25: =$C$10*(P25+Q25) -> 6651 | D25: =IFERROR(((VLOOKUP(B25,$W$11:$AB$112,3,0)+VLOOKUP(B25,$W$11:$AB$112,4,0))*$D$10),0) -> 1387.5 | E25: =R25*$E$10 -> 6597 | F25: =IFERROR(((VLOOKUP(B25,$W$11:$AB$112,5,0))*$F$10),0) -> 2387.5 | G25: =SUM(C25:F25) -> 17023 | I25: =SUM(D25:F25) -> 10372 | M25: jednicové zákazky2 | N25: 25/0136 | O25: Kostra statora DAX7-290ERJT 7 ks | P25: 369.5 | R25: 366.5 | S25: 736 | V25: jednicové zákazky2 | W25: 25/0137 | X25: Kostra statora DAX62-166 7 ks | Y25: 7.75 | AB25: 7.75
B26: =N26 -> 25/1005 | C26: =$C$10*(P26+Q26) -> 1035 | D26: =IFERROR(((VLOOKUP(B26,$W$11:$AB$112,3,0)+VLOOKUP(B26,$W$11:$AB$112,4,0))*$D$10),0) -> 1437.5 | E26: =R26*$E$10 -> 0 | F26: =IFERROR(((VLOOKUP(B26,$W$11:$AB$112,5,0))*$F$10),0) -> 0 | G26: =SUM(C26:F26) -> 2472.5 | I26: =SUM(D26:F26) -> 1437.5 | M26: jednicové zákazky2 | N26: 25/1005 | O26: SWITCH 1 segment | P26: 57.5 | S26: 57.5 | V26: jednicové zákazky2 | W26: 25/1006 | X26: Draw Bridge | Y26: 26.5 | AB26: 26.5
B27: =N27 -> 26/0004 | C27: =$C$10*(P27+Q27) -> 5184 | D27: =IFERROR(((VLOOKUP(B27,$W$11:$AB$112,3,0)+VLOOKUP(B27,$W$11:$AB$112,4,0))*$D$10),0) -> 2875 | E27: =R27*$E$10 -> 2812.5 | F27: =IFERROR(((VLOOKUP(B27,$W$11:$AB$112,5,0))*$F$10),0) -> 3906.25 | G27: =SUM(C27:F27) -> 14777.75 | I27: =SUM(D27:F27) -> 9593.75 | M27: jednicové zákazky2 | N27: 26/0004 | O27: Track | P27: 288 | R27: 156.25 | S27: 444.25 | V27: jednicové zákazky2 | W27: 26/0006 | X27: Kostra statora svarek 4 ks | Y27: 7.5 | AA27: 197 | AB27: 204.5
B28: =N28 -> 25/0088 | C28: =$C$10*(P28+Q28) -> 288 | D28: =IFERROR(((VLOOKUP(B28,$W$11:$AB$112,3,0)+VLOOKUP(B28,$W$11:$AB$112,4,0))*$D$10),0) -> 0 | E28: =R28*$E$10 -> 0 | F28: =IFERROR(((VLOOKUP(B28,$W$11:$AB$112,5,0))*$F$10),0) -> 0 | G28: =SUM(C28:F28) -> 288 | I28: =SUM(D28:F28) -> 0 | M28: jednicové zákazky2 | N28: 25/0088 | O28: SWITCH 2 | P28: 16 | S28: 16 | V28: jednicové zákazky2 | W28: 25/0110 | X28: Station - SF Fiesta Texas | Y28: 14.75 | AA28: 37.75 | AB28: 52.5
B29: =N29 -> 25/0137 | C29: =$C$10*(P29+Q29) -> 1669.5 | D29: =IFERROR(((VLOOKUP(B29,$W$11:$AB$112,3,0)+VLOOKUP(B29,$W$11:$AB$112,4,0))*$D$10),0) -> 193.75 | E29: =R29*$E$10 -> 1809 | F29: =IFERROR(((VLOOKUP(B29,$W$11:$AB$112,5,0))*$F$10),0) -> 0 | G29: =SUM(C29:F29) -> 3672.25 | I29: =SUM(D29:F29) -> 2002.75 | M29: jednicové zákazky2 | N29: 25/0137 | O29: Kostra statora DAX62-166 7 ks | P29: 92.75 | R29: 100.5 | S29: 193.25 | V29: jednicové zákazky2 | W29: 25/1008 | X29: Track Load | Y29: 106.5 | AB29: 106.5
B30: =N30 -> 25/1006 | C30: =$C$10*(P30+Q30) -> 2349 | D30: =IFERROR(((VLOOKUP(B30,$W$11:$AB$112,3,0)+VLOOKUP(B30,$W$11:$AB$112,4,0))*$D$10),0) -> 662.5 | E30: =R30*$E$10 -> 3375 | F30: =IFERROR(((VLOOKUP(B30,$W$11:$AB$112,5,0))*$F$10),0) -> 0 | G30: =SUM(C30:F30) -> 6386.5 | I30: =SUM(D30:F30) -> 4037.5 | M30: jednicové zákazky2 | N30: 25/1006 | O30: Draw Bridge | P30: 130.5 | R30: 187.5 | S30: 318 | V30: jednicové zákazky2 | W30: 25/1009 | X30: Track Unload | Y30: 7.75 | AB30: 7.75
B31: =N31 -> 25/1007 | C31: =$C$10*(P31+Q31) -> 666 | D31: =IFERROR(((VLOOKUP(B31,$W$11:$AB$112,3,0)+VLOOKUP(B31,$W$11:$AB$112,4,0))*$D$10),0) -> 0 | E31: =R31*$E$10 -> 0 | F31: =IFERROR(((VLOOKUP(B31,$W$11:$AB$112,5,0))*$F$10),0) -> 0 | G31: =SUM(C31:F31) -> 666 | I31: =SUM(D31:F31) -> 0 | M31: jednicové zákazky2 | N31: 25/1007 | O31: Track Hold | P31: 37 | S31: 37 | V31: jednicové zákazky2 | W31: 26/0018 | X31: Kostra statora DG215ZU-04 3 ks | Y31: 126.25 | AA31: 67 | AB31: 193.25
B32: =N32 -> 26/0006 | C32: =$C$10*(P32+Q32) -> 6147 | D32: =IFERROR(((VLOOKUP(B32,$W$11:$AB$112,3,0)+VLOOKUP(B32,$W$11:$AB$112,4,0))*$D$10),0) -> 187.5 | E32: =R32*$E$10 -> 3762 | F32: =IFERROR(((VLOOKUP(B32,$W$11:$AB$112,5,0))*$F$10),0) -> 4925 | G32: =SUM(C32:F32) -> 15021.5 | I32: =SUM(D32:F32) -> 8874.5 | M32: jednicové zákazky2 | N32: 26/0006 | O32: Kostra statora svarek 4 ks | P32: 341.5 | R32: 209 | S32: 550.5 | V32: jednicové zákazky2 | W32: 25/0111 | X32: Launch - SF Fiesta Texas | Y32: 180.25 | AA32: 39.25 | AB32: 219.5
B33: =N33 -> 25/0110 | C33: =$C$10*(P33+Q33) -> 985.5 | D33: =IFERROR(((VLOOKUP(B33,$W$11:$AB$112,3,0)+VLOOKUP(B33,$W$11:$AB$112,4,0))*$D$10),0) -> 368.75 | E33: =R33*$E$10 -> 967.5 | F33: =IFERROR(((VLOOKUP(B33,$W$11:$AB$112,5,0))*$F$10),0) -> 943.75 | G33: =SUM(C33:F33) -> 3265.5 | I33: =SUM(D33:F33) -> 2280 | M33: jednicové zákazky2 | N33: 25/0110 | O33: Station - SF Fiesta Texas | P33: 54.75 | R33: 53.75 | S33: 108.5 | V33: jednicové zákazky2 | W33: 25/1010 | X33: Track Launch | Y33: 100.75 | AA33: 85.75 | AB33: 186.5
B34: =N34 -> 25/1008 | C34: =$C$10*(P34+Q34) -> 4374 | D34: =IFERROR(((VLOOKUP(B34,$W$11:$AB$112,3,0)+VLOOKUP(B34,$W$11:$AB$112,4,0))*$D$10),0) -> 2662.5 | E34: =R34*$E$10 -> 8523 | F34: =IFERROR(((VLOOKUP(B34,$W$11:$AB$112,5,0))*$F$10),0) -> 0 | G34: =SUM(C34:F34) -> 15559.5 | I34: =SUM(D34:F34) -> 11185.5 | M34: jednicové zákazky2 | N34: 25/1008 | O34: Track Load | P34: 243 | R34: 473.5 | S34: 716.5 | V34: jednicové zákazky2 | W34: 26/0017 | X34: Rám zakladovy opracovanie DG215 1 ks | AA34: 10.5 | AB34: 10.5
B35: =N35 -> 25/1009 | C35: =$C$10*(P35+Q35) -> 139.5 | D35: =IFERROR(((VLOOKUP(B35,$W$11:$AB$112,3,0)+VLOOKUP(B35,$W$11:$AB$112,4,0))*$D$10),0) -> 193.75 | E35: =R35*$E$10 -> 1233 | F35: =IFERROR(((VLOOKUP(B35,$W$11:$AB$112,5,0))*$F$10),0) -> 0 | G35: =SUM(C35:F35) -> 1566.25 | I35: =SUM(D35:F35) -> 1426.75 | M35: jednicové zákazky2 | N35: 25/1009 | O35: Track Unload | P35: 7.75 | R35: 68.5 | S35: 76.25 | V35: jednicové zákazky2 | W35: 26/0020 | X35: Cam rail hub 1 ks | Y35: 7.75 | AA35: 21.5 | AB35: 29.25
B36: =N36 -> 26/0018 | C36: =$C$10*(P36+Q36) -> 5341.5 | D36: =IFERROR(((VLOOKUP(B36,$W$11:$AB$112,3,0)+VLOOKUP(B36,$W$11:$AB$112,4,0))*$D$10),0) -> 3156.25 | E36: =R36*$E$10 -> 1890 | F36: =IFERROR(((VLOOKUP(B36,$W$11:$AB$112,5,0))*$F$10),0) -> 1675 | G36: =SUM(C36:F36) -> 12062.75 | I36: =SUM(D36:F36) -> 6721.25 | M36: jednicové zákazky2 | N36: 26/0018 | O36: Kostra statora DG215ZU-04 3 ks | P36: 296.75 | R36: 105 | S36: 401.75 | V36: jednicové zákazky2 | W36: 26/0024 | X36: Gehäuse 1 ks | Y36: 34 | AB36: 34
B37: =N37 -> 25/0111 | C37: =$C$10*(P37+Q37) -> 5116.5 | D37: =IFERROR(((VLOOKUP(B37,$W$11:$AB$112,3,0)+VLOOKUP(B37,$W$11:$AB$112,4,0))*$D$10),0) -> 4506.25 | E37: =R37*$E$10 -> 3676.5 | F37: =IFERROR(((VLOOKUP(B37,$W$11:$AB$112,5,0))*$F$10),0) -> 981.25 | G37: =SUM(C37:F37) -> 14280.5 | I37: =SUM(D37:F37) -> 9164 | M37: jednicové zákazky2 | N37: 25/0111 | O37: Launch - SF Fiesta Texas | P37: 284.25 | R37: 204.25 | S37: 488.5 | V37: jednicové zákazky2 | W37: 26/0028 | X37: Kostra statora BDAX7-185ER 1 ks | AA37: 30.75 | AB37: 30.75
B38: =N38 -> 25/1010 | C38: =$C$10*(P38+Q38) -> 4450.5 | D38: =IFERROR(((VLOOKUP(B38,$W$11:$AB$112,3,0)+VLOOKUP(B38,$W$11:$AB$112,4,0))*$D$10),0) -> 2518.75 | E38: =R38*$E$10 -> 18661.5 | F38: =IFERROR(((VLOOKUP(B38,$W$11:$AB$112,5,0))*$F$10),0) -> 2143.75 | G38: =SUM(C38:F38) -> 27774.5 | I38: =SUM(D38:F38) -> 23324 | M38: jednicové zákazky2 | N38: 25/1010 | O38: Track Launch | P38: 247.25 | R38: 1036.75 | S38: 1284 | V38: jednicové zákazky2 | W38: 25/0112 | X38: Storage - SF Fiesta Texas 3 ks | Y38: 18.75 | AA38: 7 | AB38: 25.75
B39: =N39 -> 26/0011 | C39: =$C$10*(P39+Q39) -> 144 | D39: =IFERROR(((VLOOKUP(B39,$W$11:$AB$112,3,0)+VLOOKUP(B39,$W$11:$AB$112,4,0))*$D$10),0) -> 0 | E39: =R39*$E$10 -> 1593 | F39: =IFERROR(((VLOOKUP(B39,$W$11:$AB$112,5,0))*$F$10),0) -> 0 | G39: =SUM(C39:F39) -> 1737 | I39: =SUM(D39:F39) -> 1593 | M39: jednicové zákazky2 | N39: 26/0011 | O39: Camrail 61 ks | P39: 8 | R39: 88.5 | S39: 96.5 | V39: jednicové zákazky2 | W39: 25/0142 | X39: Brakezone - SF Fiesta Texas | Y39: 23.25 | AA39: 5.25 | AB39: 28.5
B40: =N40 -> 26/0017 | C40: =$C$10*(P40+Q40) -> 0 | D40: =IFERROR(((VLOOKUP(B40,$W$11:$AB$112,3,0)+VLOOKUP(B40,$W$11:$AB$112,4,0))*$D$10),0) -> 0 | E40: =R40*$E$10 -> 189 | F40: =IFERROR(((VLOOKUP(B40,$W$11:$AB$112,5,0))*$F$10),0) -> 262.5 | G40: =SUM(C40:F40) -> 451.5 | I40: =SUM(D40:F40) -> 451.5 | M40: jednicové zákazky2 | N40: 26/0017 | O40: Rám zakladovy opracovanie DG215 1 ks | R40: 10.5 | S40: 10.5 | V40: jednicové zákazky2 | W40: 25/1011 | X40: Brake Zone | Y40: 4.75 | AA40: 7 | AB40: 11.75
B41: =N41 -> 26/0019 | C41: =$C$10*(P41+Q41) -> 7506 | D41: =IFERROR(((VLOOKUP(B41,$W$11:$AB$112,3,0)+VLOOKUP(B41,$W$11:$AB$112,4,0))*$D$10),0) -> 0 | E41: =R41*$E$10 -> 1458 | F41: =IFERROR(((VLOOKUP(B41,$W$11:$AB$112,5,0))*$F$10),0) -> 0 | G41: =SUM(C41:F41) -> 8964 | I41: =SUM(D41:F41) -> 1458 | M41: jednicové zákazky2 | N41: 26/0019 | O41: Kostra statora BDAX72-265ER 3 ks | P41: 417 | R41: 81 | S41: 498 | V41: jednicové zákazky2 | W41: 26/0001 | X41: Track 3D 49 ks | Y41: 100.5 | AA41: 9.25 | AB41: 109.75
B42: =N42 -> 26/0020 | C42: =$C$10*(P42+Q42) -> 5121 | D42: =IFERROR(((VLOOKUP(B42,$W$11:$AB$112,3,0)+VLOOKUP(B42,$W$11:$AB$112,4,0))*$D$10),0) -> 193.75 | E42: =R42*$E$10 -> 747 | F42: =IFERROR(((VLOOKUP(B42,$W$11:$AB$112,5,0))*$F$10),0) -> 537.5 | G42: =SUM(C42:F42) -> 6599.25 | I42: =SUM(D42:F42) -> 1478.25 | M42: jednicové zákazky2 | N42: 26/0020 | O42: Cam rail hub 1 ks | P42: 284.5 | R42: 41.5 | S42: 326 | V42: jednicové zákazky2 | W42: 26/0002 | X42: Station/Hold | Y42: 39.5 | AA42: 20.5 | AB42: 60
B43: =N43 -> 26/0024 | C43: =$C$10*(P43+Q43) -> 828 | D43: =IFERROR(((VLOOKUP(B43,$W$11:$AB$112,3,0)+VLOOKUP(B43,$W$11:$AB$112,4,0))*$D$10),0) -> 850 | E43: =R43*$E$10 -> 0 | F43: =IFERROR(((VLOOKUP(B43,$W$11:$AB$112,5,0))*$F$10),0) -> 0 | G43: =SUM(C43:F43) -> 1678 | I43: =SUM(D43:F43) -> 850 | M43: jednicové zákazky2 | N43: 26/0024 | O43: Gehäuse 1 ks | P43: 46 | S43: 46 | V43: jednicové zákazky2 | W43: 26/0003 | X43: Launch | Y43: 69.75 | AB43: 69.75
...

Sheet 2018_12_rozpočet_RN_zakazky_B
B2: ='2026_06_rozpočet_RN_sumar'!D54 -> B) Dopočítaná vyššia sadzba na VP3M a VP3V: ohýbanie, skružovanie, sústruženie | K2: =K46 -> 0 | L2: =K2='2026_06_rozpočet_RN_sumar'!#REF! -> #REF!
B4: obdobie | C4: (Všetko)
B5: Výrobný úsek | C5: (Viacero položiek) | D5: JR+ŽN z úkolu
B6: Kategória2 | C6: (Viacero položiek)
B8: Súčet z Spolu [hod] | E8: Stredisko
B9: nm_typ_zákazky | C9: Zakazka_upr | D9: Názov zákazky | E9: Ohýbanie | F9: Skružovanie | G9: Sústruženie | H9: Vŕtanie | I9: Spolu | L9: Zákazka
B10: 8_drobné zákazky | C10: XX/9999 | D10: Podniková réžia | L10: =C10 -> XX/9999
C11: XX/9999 | D11: (prázdne) | L11: =C11 -> XX/9999
C12: XX/9999 | D12: Gehäuse 2 ks | L12: =C12 -> XX/9999
C13: XX/9999 | D13: Gehäuse 1 ks | L13: =C13 -> XX/9999
C14: XX/9999 | D14: Oprava a udržiavanie majetku | L14: =C14 -> XX/9999
C15: XX/9999 | D15: Stĺpy | L15: =C15 -> XX/9999
C16: XX/9999 | D16: Dráha | L16: =C16 -> XX/9999
C17: XX/9999 | D17: Trommelkörper 1 ks | L17: =C17 -> XX/9999
C18: XX/9999 | D18: Dielce | L18: =C18 -> XX/9999
C19: XX/9999 | D19: 3D Dráha | L19: =C19 -> XX/9999
C20: XX/9999 | D20: Základový rám 1 ks | L20: =C20 -> XX/9999
C21: XX/9999 | D21: VRTB náklady na pracovisko | L21: =C21 -> XX/9999
C22: XX/9999 | D22: Brake Zone | L22: =C22 -> XX/9999
... C46: XX/9999 | D46: Track Unload | L46: =C46 -> XX/9999
C47: XX/9999 | D47: Kostra statora DG215ZU-04 3 ks
C48: XX/9999 | D48: Launch - SF Fiesta Texas
C49: XX/9999 | D49: Track Launch
C50: XX/9999 | D50: Camrail 61 ks
C51: XX/9999 | D51: Rám zakladovy opracovanie DG215 1 ks
C52: XX/9999 | D52: Kostra statora BDAX72-265ER 3 ks
C53: XX/9999 | D53: Cam rail hub 1 ks
C54: XX/9999 | D54: Kostra statora BDAX7-185ER 1 ks
C55: XX/9999 | D55: Storage - SF Fiesta Texas 3 ks
C56: XX/9999 | D56: Switch - SF Fiesta Texas
C57: XX/9999 | D57: Brakezone - SF Fiesta Texas
C58: XX/9999 | D58: Track 3D 49 ks
... C4361: 26/8030 | D4361: 3D pálenie rúry 1 ks
B4362: 8_drobné zákazky Celková hodnota
B4363: jednicové zákazky2 | C4363: 25/1003 | D4363: 2D ku SWITCH | H4363: 16 | I4363: 16
C4364: 26/0004 | D4364: Track | H4364: 24 | I4364: 24
C4365: 25/0137 | D4365: Kostra statora DAX62-166 7 ks | E4365: 3 | I4365: 3
C4366: 25/1006 | D4366: Draw Bridge | E4366: 33 | I4366: 33
C4367: 25/1007 | D4367: Track Hold | F4367: 8 | H4367: 16 | I4367: 24
C4368: 25/0110 | D4368: Station - SF Fiesta Texas | H4368: 16 | I4368: 16
...

Sheet 2019_09_rozpočet_RN_zakazky_C
B2: ='2026_06_rozpočet_RN_sumar'!D14 -> c) Výpočet réžie - pre neodvedené hodiny podľa časového fondu (plánu) | F2: =G2 -> 166538.3 | G2: 166538.3 | H2: ukončené zákazky
B4: Zákazka | C4: Odved h. | D4: % podiel | E4: Doučtovanie neodved. H.
B5: =TRIM('2026_06_rozpočet_RN_zakazky_A'!B11) -> 23/0082 | C5: ='2026_06_rozpočet_RN_zakazky_A'!S11 -> 71.5 | D5: =C5/SUM($C$5:$C$102) -> 0.0045716113 | E5: =D5*'2026_06_rozpočet_RN_sumar'!$I$81 -> -424.6404
B6: =TRIM('2026_06_rozpočet_RN_zakazky_A'!B12) -> 23/0083 | C6: ='2026_06_rozpočet_RN_zakazky_A'!S12 -> 100.5 | D6: =C6/SUM($C$5:$C$151) -> #REF! | E6: =D6*'2026_06_rozpočet_RN_sumar'!$I$81 -> #REF!
B7: =TRIM('2026_06_rozpočet_RN_zakazky_A'!B13) -> 23/0084 | C7: ='2026_06_rozpočet_RN_zakazky_A'!S13 -> 28 | D7: =C7/SUM($C$5:$C$151) -> #REF! | E7: =D7*'2026_06_rozpočet_RN_sumar'!$I$81 -> #REF!
B8: =TRIM('2026_06_rozpočet_RN_zakazky_A'!B14) -> 25/0055 | C8: ='2026_06_rozpočet_RN_zakazky_A'!S14 -> 744 | D8: =C8/SUM($C$5:$C$151) -> #REF! | E8: =D8*'2026_06_rozpočet_RN_sumar'!$I$81 -> #REF!
B9: =TRIM('2026_06_rozpočet_RN_zakazky_A'!B15) -> 25/1002 | C9: ='2026_06_rozpočet_RN_zakazky_A'!S15 -> 359.25 | D9: =C9/SUM($C$5:$C$151) -> #REF! | E9: =D9*'2026_06_rozpočet_RN_sumar'!$I$81 -> #REF!
B10: =TRIM('2026_06_rozpočet_RN_zakazky_A'!B16) -> 25/0095 | C10: ='2026_06_rozpočet_RN_zakazky_A'!S16 -> 1233.5 | D10: =C10/SUM($C$5:$C$151) -> #REF! | E10: =D10*'2026_06_rozpočet_RN_sumar'!$I$81 -> #REF!
B11: =TRIM('2026_06_rozpočet_RN_zakazky_A'!B17) -> 25/1001 | C11: ='2026_06_rozpočet_RN_zakazky_A'!S17 -> 1072 | D11: =C11/SUM($C$5:$C$151) -> #REF! | E11: =D11*'2026_06_rozpočet_RN_sumar'!$I$81 -> #REF!
B12: =TRIM('2026_06_rozpočet_RN_zakazky_A'!B18) -> 25/1003 | C12: ='2026_06_rozpočet_RN_zakazky_A'!S18 -> 74 | D12: =C12/SUM($C$5:$C$151) -> #REF! | E12: =D12*'2026_06_rozpočet_RN_sumar'!$I$81 -> #REF!
B13: =TRIM('2026_06_rozpočet_RN_zakazky_A'!B19) -> 25/0109 | C13: ='2026_06_rozpočet_RN_zakazky_A'!S19 -> 202.75 | D13: =C13/SUM($C$5:$C$151) -> #REF! | E13: =D13*'2026_06_rozpočet_RN_sumar'!$I$81 -> #REF!
B14: =TRIM('2026_06_rozpočet_RN_zakazky_A'!B20) -> 25/0115 | C14: ='2026_06_rozpočet_RN_zakazky_A'!S20 -> 54 | D14: =C14/SUM($C$5:$C$151) -> #REF! | E14: =D14*'2026_06_rozpočet_RN_sumar'!$I$81 -> #REF!
B15: =TRIM('2026_06_rozpočet_RN_zakazky_A'!B21) -> 25/0122 | C15: ='2026_06_rozpočet_RN_zakazky_A'!S21 -> 8 | D15: =C15/SUM($C$5:$C$151) -> #REF! | E15: =D15*'2026_06_rozpočet_RN_sumar'!$I$81 -> #REF!
B16: =TRIM('2026_06_rozpočet_RN_zakazky_A'!B22) -> 25/0133 | C16: ='2026_06_rozpočet_RN_zakazky_A'!S22 -> 8 | D16: =C16/SUM($C$5:$C$151) -> #REF! | E16: =D16*'2026_06_rozpočet_RN_sumar'!$I$81 -> #REF!
B17: =TRIM('2026_06_rozpočet_RN_zakazky_A'!B23) -> 25/1004 | C17: ='2026_06_rozpočet_RN_zakazky_A'!S23 -> 130.5 | D17: =C17/SUM($C$5:$C$151) -> #REF! | E17: =D17*'2026_06_rozpočet_RN_sumar'!$I$81 -> #REF!
... B102: =TRIM('2026_06_rozpočet_RN_zakazky_A'!B108) -> 0 | C102: ='2026_06_rozpočet_RN_zakazky_A'!S108 -> 0 | D102: =C102/SUM($C$5:$C$151) -> #REF! | E102: =D102*'2026_06_rozpočet_RN_sumar'!$I$81 -> #REF!
B103: =TRIM('2026_06_rozpočet_RN_zakazky_A'!B109) -> 0 | C103: ='2026_06_rozpočet_RN_zakazky_A'!S109 -> 0 | D103: =C103/SUM($C$5:$C$151) -> #REF! | E103: =D103*'2026_06_rozpočet_RN_sumar'!$I$81*-1 -> #REF!
B104: =TRIM('2026_06_rozpočet_RN_zakazky_A'!B110) -> 0 | C104: ='2026_06_rozpočet_RN_zakazky_A'!S110 -> 0 | D104: =C104/SUM($C$5:$C$151) -> #REF! | E104: =D104*'2026_06_rozpočet_RN_sumar'!$I$81*-1 -> #REF!
B105: =TRIM('2026_06_rozpočet_RN_zakazky_A'!B111) -> 0 | C105: ='2026_06_rozpočet_RN_zakazky_A'!S111 -> 0 | D105: =C105/SUM($C$5:$C$151) -> #REF! | E105: =D105*'2026_06_rozpočet_RN_sumar'!$I$81*-1 -> #REF!
B106: =TRIM('2026_06_rozpočet_RN_zakazky_A'!B112) -> 0 | C106: ='2026_06_rozpočet_RN_zakazky_A'!S112 -> 0 | D106: =C106/SUM($C$5:$C$151) -> #REF! | E106: =D106*'2026_06_rozpočet_RN_sumar'!$I$81*-1 -> #REF!
B107: =TRIM('2026_06_rozpočet_RN_zakazky_A'!#REF!) -> #REF! | C107: ='2026_06_rozpočet_RN_zakazky_A'!#REF! -> #REF! | D107: =C107/SUM($C$5:$C$151) -> #REF! | E107: =D107*'2026_06_rozpočet_RN_sumar'!$I$81*-1 -> #REF!
B108: =TRIM('2026_06_rozpočet_RN_zakazky_A'!#REF!) -> #REF! | C108: ='2026_06_rozpočet_RN_zakazky_A'!#REF! -> #REF! | D108: =C108/SUM($C$5:$C$151) -> #REF! | E108: =D108*'2026_06_rozpočet_RN_sumar'!$I$81*-1 -> #REF!
B109: =TRIM('2026_06_rozpočet_RN_zakazky_A'!#REF!) -> #REF! | C109: ='2026_06_rozpočet_RN_zakazky_A'!#REF! -> #REF! | D109: =C109/SUM($C$5:$C$151) -> #REF! | E109: =D109*'2026_06_rozpočet_RN_sumar'!$I$81*-1 -> #REF!
B110: =TRIM('2026_06_rozpočet_RN_zakazky_A'!#REF!) -> #REF! | C110: ='2026_06_rozpočet_RN_zakazky_A'!#REF! -> #REF! | D110: =C110/SUM($C$5:$C$151) -> #REF! | E110: =D110*'2026_06_rozpočet_RN_sumar'!$I$81*-1 -> #REF!
B111: =TRIM('2026_06_rozpočet_RN_zakazky_A'!#REF!) -> #REF! | C111: ='2026_06_rozpočet_RN_zakazky_A'!#REF! -> #REF! | D111: =C111/SUM($C$5:$C$151) -> #REF! | E111: =D111*'2026_06_rozpočet_RN_sumar'!$I$81*-1 -> #REF!
B112: =TRIM('2026_06_rozpočet_RN_zakazky_A'!#REF!) -> #REF! | C112: ='2026_06_rozpočet_RN_zakazky_A'!#REF! -> #REF! | D112: =C112/SUM($C$5:$C$151) -> #REF! | E112: =D112*'2026_06_rozpočet_RN_sumar'!$I$81*-1 -> #REF!
B113: =TRIM('2026_06_rozpočet_RN_zakazky_A'!#REF!) -> #REF! | C113: ='2026_06_rozpočet_RN_zakazky_A'!#REF! -> #REF! | D113: =C113/SUM($C$5:$C$151) -> #REF! | E113: =D113*'2026_06_rozpočet_RN_sumar'!$I$81*-1 -> #REF!
B114: =TRIM('2026_06_rozpočet_RN_zakazky_A'!#REF!) -> #REF! | C114: ='2026_06_rozpočet_RN_zakazky_A'!#REF! -> #REF! | D114: =C114/SUM($C$5:$C$151) -> #REF! | E114: =D114*'2026_06_rozpočet_RN_sumar'!$I$81*-1 -> #REF!
B115: =TRIM('2026_06_rozpočet_RN_zakazky_A'!#REF!) -> #REF! | C115: ='2026_06_rozpočet_RN_zakazky_A'!#REF! -> #REF! | D115: =C115/SUM($C$5:$C$151) -> #REF! | E115: =D115*'2026_06_rozpočet_RN_sumar'!$I$81*-1 -> #REF!
B116: =TRIM('2026_06_rozpočet_RN_zakazky_A'!#REF!) -> #REF! | C116: ='2026_06_rozpočet_RN_zakazky_A'!#REF! -> #REF! | D116: =C116/SUM($C$5:$C$151) -> #REF! | E116: =D116*'2026_06_rozpočet_RN_sumar'!$I$81*-1 -> #REF!
B117: =TRIM('2026_06_rozpočet_RN_zakazky_A'!#REF!) -> #REF! | C117: ='2026_06_rozpočet_RN_zakazky_A'!#REF! -> #REF! | D117: =C117/SUM($C$5:$C$151) -> #REF! | E117: =D117*'2026_06_rozpočet_RN_sumar'!$I$81*-1 -> #REF!
B118: =TRIM('2026_06_rozpočet_RN_zakazky_A'!#REF!) -> #REF! | C118: ='2026_06_rozpočet_RN_zakazky_A'!#REF! -> #REF! | D118: =C118/SUM($C$5:$C$151) -> #REF! | E118: =D118*'2026_06_rozpočet_RN_sumar'!$I$81*-1 -> #REF!
... B151: =TRIM('2026_06_rozpočet_RN_zakazky_A'!#REF!) -> #REF! | C151: ='2026_06_rozpočet_RN_zakazky_A'!#REF! -> #REF! | D151: =C151/SUM($C$5:$C$151) -> #REF! | E151: =D151*'2026_06_rozpočet_RN_sumar'!$I$81*-1 -> #REF!

Sheet 2018_11_vykazane_hod_zakazky
C4: Zákazka | D4: Vykázané
D5: (platené) | F5: obdobie | G5: (Všetko)
C6: Celkom : | D6: =SUM(D7:D1048576) -> 691 | E6: =D6='2026_06_sumar'!E22 -> FALSE
C7: Drobné zákazky (XX/8000-8999) | D7: ='2026_06_sumar'!F43 -> 432 | I7: Hodnoty
C8: XX/9999 - Podniková réžia + ŠKOLENIE: 12,5h | D8: ='2026_06_sumar'!M36 -> 259 | F8: nm_typ_zákazky | G8: Zakazka_upr | H8: Názov zákazky | I8: Súčet z Spolu [hod] | J8: Počet z Výrobný úsek
F9: jednicové zákazky2 | G9: 23/0082 | H9: Základový rám 1 ks | I9: 71.5 | J9: 5 | K9: =VLOOKUP(G9,$L$9:$N$101,2,0) -> #N/A | L9: =LEFT(M9,7) -> 14/0075 | M9: 14/0075 (k 13/0142)ZIERER Dráha
B10: =LEFT(C10,7) -> 14/0075 | C10: 14/0075 (k 13/0142)ZIERER Dráha | D10: =IFERROR(VLOOKUP(B10,$G$8:$I$1048576,3,0),0) -> 0 | F10: jednicové zákazky2 | G10: 23/0083 | H10: Základový rám 1 ks | I10: 100.5 | J10: 6 | K10: =VLOOKUP(G10,$L$9:$N$101,2,0) -> #N/A | L10: =LEFT(M10,7) -> 14/0173 | M10: 14/0173 BRUSH CZ Svarek kostry statoru
B11: =LEFT(C11,7) -> 14/0173 | C11: 14/0173 BRUSH CZ Svarek kostry statoru | D11: =IFERROR(VLOOKUP(B11,$G$8:$I$1048576,3,0),0) -> 0 | F11: jednicové zákazky2 | G11: 23/0084 | H11: Základový rám 1 ks | I11: 28 | J11: 3 | K11: =VLOOKUP(G11,$L$9:$N$101,2,0) -> #N/A | L11: =LEFT(M11,7) -> 15/0190 | M11: 15/0190 GE ENERGY Base frame
B12: =LEFT(C12,7) -> 15/0190 | C12: 15/0190 GE ENERGY Base frame | D12: =IFERROR(VLOOKUP(B12,$G$8:$I$1048576,3,0),0) -> 0 | F12: jednicové zákazky2 | G12: 25/0055 | H12: 3D Dráha | I12: 744 | J12: 9 | K12: =VLOOKUP(G12,$L$9:$N$101,2,0) -> #N/A | L12: =LEFT(M12,7) -> 16/0007 | M12: 16/0007 BRUSH CZ Stator
B13: =LEFT(C13,7) -> 16/0007 | C13: 16/0007 BRUSH CZ Stator | D13: =IFERROR(VLOOKUP(B13,$G$8:$I$1048576,3,0),0) -> 0 | F13: jednicové zákazky2 | G13: 25/1002 | H13: SWITCH 9ks | I13: 359.25 | J13: 6 | K13: =VLOOKUP(G13,$L$9:$N$101,2,0) -> #N/A | L13: =LEFT(M13,7) -> 16/0091 | M13: 16/0091 VEKOMA 3D Dráha Phantasialand
B14: =LEFT(C14,7) -> 16/0091 | C14: 16/0091 VEKOMA 3D Dráha Phantasialand | D14: =IFERROR(VLOOKUP(B14,$G$8:$I$1048576,3,0),0) -> 0 | F14: jednicové zákazky2 | G14: 25/0095 | H14: 3D DRÁHA - FBCD Karls Erlebnisdorf | I14: 1233.5 | J14: 8 | K14: =VLOOKUP(G14,$L$9:$N$101,2,0) -> #N/A | L14: =LEFT(M14,7) -> 16/0163 | M14: 16/0163 GE ENERGY Socle
B15: =LEFT(C15,7) -> 16/0163 | C15: 16/0163 GE ENERGY Socle | D15: =IFERROR(VLOOKUP(B15,$G$8:$I$1048576,3,0),0) -> 0 | F15: jednicové zákazky2 | G15: 25/1001 | H15: 3D Dráha 68 ks | I15: 1072 | J15: 9 | K15: =VLOOKUP(G15,$L$9:$N$101,2,0) -> #N/A | L15: =LEFT(M15,7) -> 16/0164 | M15: 16/0164 GE ENERGY Socle
B16: =LEFT(C16,7) -> 16/0164 | C16: 16/0164 GE ENERGY Socle | D16: =IFERROR(VLOOKUP(B16,$G$8:$I$1048576,3,0),0) -> 0 | F16: jednicové zákazky2 | G16: 25/1003 | H16: 2D ku SWITCH | I16: 74 | J16: 5 | K16: =VLOOKUP(G16,$L$9:$N$101,2,0) -> #N/A | L16: =LEFT(M16,7) -> 16/0192 | M16: 16/0192 VEKOMA Switch
B17: =LEFT(C17,7) -> 16/0192 | C17: 16/0192 VEKOMA Switch | D17: =IFERROR(VLOOKUP(B17,$G$8:$I$1048576,3,0),0) -> 0 | F17: jednicové zákazky2 | G17: 25/0109 | H17: 3D Dráha - SF Fiesta Texas | I17: 202.75 | J17: 8 | K17: =VLOOKUP(G17,$L$9:$N$101,2,0) -> #N/A | L17: =LEFT(M17,7) -> 16/0193 | M17: 16/0193 VEKOMA Launch
B18: =LEFT(C18,7) -> 16/0193 | C18: 16/0193 VEKOMA Launch | D18: =IFERROR(VLOOKUP(B18,$G$8:$I$1048576,3,0),0) -> 0 | F18: jednicové zákazky2 | G18: 25/0115 | H18: Kostra statora DAX7-290ERJT 3 ks | I18: 54 | J18: 2 | K18: =VLOOKUP(G18,$L$9:$N$101,2,0) -> #N/A | L18: =LEFT(M18,7) -> 16/0195 | M18: 16/0195 VEKOMA Trim, Station
B19: =LEFT(C19,7) -> 16/0195 | C19: 16/0195 VEKOMA Trim, Station | D19: =IFERROR(VLOOKUP(B19,$G$8:$I$1048576,3,0),0) -> 0 | F19: jednicové zákazky2 | G19: 25/0122 | H19: Kostra statora BDAX7-168ER 3 ks | I19: 8 | J19: 1 | K19: =VLOOKUP(G19,$L$9:$N$101,2,0) -> #N/A | L19: =LEFT(M19,7) -> 17/0037 | M19: 17/0037 GE ENERGY Base Frame
B20: =LEFT(C20,7) -> 17/0037 | C20: 17/0037 GE ENERGY Base Frame | D20: =IFERROR(VLOOKUP(B20,$G$8:$I$1048576,3,0),0) -> 0 | F20: jednicové zákazky2 | G20: 25/0133 | H20: Kostra statora DAX7-145ER 2 ks | I20: 8 | J20: 1 | K20: =VLOOKUP(G20,$L$9:$N$101,2,0) -> #N/A | L20: =LEFT(M20,7) -> 17/0103 | M20: 17/0103 GE ENERGY Base Frame Standard
B21: =LEFT(C21,7) -> 17/0103 | C21: 17/0103 GE ENERGY Base Frame Standard | D21: =IFERROR(VLOOKUP(B21,$G$8:$I$1048576,3,0),0) -> 0 | F21: jednicové zákazky2 | G21: 25/1004 | H21: 2D SHOW | I21: 130.5 | J21: 3 | K21: =VLOOKUP(G21,$L$9:$N$101,2,0) -> #N/A | L21: =LEFT(M21,7) -> 17/0104 | M21: 17/0104 GE ENERGY Base Frame Standard
... B65: =LEFT(C65,7) -> 18/0096 | C65: 18/0096 VEM Stator | D65: =IFERROR(VLOOKUP(B65,$G$8:$I$1048576,3,0),0) -> 0 | F65: jednicové zákazky2 | G65: 26/0050 | H65: Trommelkörper 1 ks | I65: 15.75 | J65: 1 | K65: =VLOOKUP(G65,$L$9:$N$101,2,0) -> #N/A | L65: =LEFT(M65,7) -> 18/0078 | M65: 18/0078 BTS MAURER Spike Coaster Mirabilandia
B66: =LEFT(C66,7) -> 18/0097 | C66: 18/0097 BRUSH CZ Kostra statora | D66: =IFERROR(VLOOKUP(B66,$G$8:$I$1048576,3,0),0) -> 0 | F66: jednicové zákazky2 Celková hodnota | I66: 15615.5 | J66: 320 | K66: =VLOOKUP(G66,$L$9:$N$101,2,0) -> #N/A | L66: =LEFT(M66,7) -> 18/0080 | M66: 18/0080 GE ENERGY Base Frame
B67: =LEFT(C67,7) -> 18/0099 | C67: 18/0099 VEM Gehäuse | D67: =IFERROR(VLOOKUP(B67,$G$8:$I$1048576,3,0),0) -> 0 | F67: 8_drobné zákazky | G67: 26/8006 | H67: Pálenie, skruž.+materiál 2 ks | I67: 3.5 | J67: 1 | K67: =VLOOKUP(G67,$L$9:$N$101,2,0) -> #N/A | L67: =LEFT(M67,7) -> 18/0081 | M67: 18/0081 VEKOMA Sausalito Coaster
B68: =LEFT(C68,7) -> 18/0100 | C68: 18/0100 VEKOMA Oprava lávky | D68: =IFERROR(VLOOKUP(B68,$G$8:$I$1048576,3,0),0) -> 0 | F68: 8_drobné zákazky | G68: 26/8025 | H68: Pálenie | I68: 3 | J68: 1 | K68: =VLOOKUP(G68,$L$9:$N$101,2,0) -> #N/A | L68: =LEFT(M68,7) -> 18/0086 | M68: 18/0086 VEM Pressring
B69: =LEFT(C69,7) -> 18/0101 | C69: 18/0101 VEKOMA_2D Tr.tation B_Sausali | D69: =IFERROR(VLOOKUP(B69,$G$8:$I$1048576,3,0),0) -> 0 | F69: 8_drobné zákazky | G69: 26/8003 | H69: Pálenie 5 ks | I69: 2 | J69: 1 | K69: =VLOOKUP(G69,$L$9:$N$101,2,0) -> #N/A | L69: =LEFT(M69,7) -> 18/0087 | M69: 18/0087 VEM Stator
B70: =LEFT(C70,7) -> 18/0102 | C70: 18/0102 BRUSH_2x_bearing shield | D70: =IFERROR(VLOOKUP(B70,$G$8:$I$1048576,3,0),0) -> 0 | F70: 8_drobné zákazky | G70: 26/8029 | H70: Zváranie 1 ks | I70: 10 | J70: 1 | K70: =VLOOKUP(G70,$L$9:$N$101,2,0) -> #N/A | L70: =LEFT(M70,7) -> 18/0088 | M70: 18/0088 VEM Stator
B71: =LEFT(C71,7) -> 18/0103 | C71: 18/0103 BRUSH Stator for a DG | D71: =IFERROR(VLOOKUP(B71,$G$8:$I$1048576,3,0),0) -> 0 | F71: 8_drobné zákazky | G71: 26/8030 | H71: 3D pálenie rúry 1 ks | I71: 6 | J71: 2 | K71: =VLOOKUP(G71,$L$9:$N$101,2,0) -> #N/A | L71: =LEFT(M71,7) -> 18/0089 | M71: 18/0089 BRUSH CZ Kostra statora
B72: =LEFT(C72,7) -> 18/0105 | C72: 18/0105 VEM Stator | D72: =IFERROR(VLOOKUP(B72,$G$8:$I$1048576,3,0),0) -> 0 | F72: 8_drobné zákazky Celková hodnota | I72: 24.5 | J72: 6 | K72: =VLOOKUP(G72,$L$9:$N$101,2,0) -> #N/A | L72: =LEFT(M72,7) -> 18/0091 | M72: 18/0091 GERSTLAUER Lagerring
B73: =LEFT(C73,7) -> 18/0106 | C73: 18/0106 VEM Stator | D73: =IFERROR(VLOOKUP(B73,$G$8:$I$1048576,3,0),0) -> 0 | F73: 5_režijné zákazky | G73: 26/5002 | H73: Oprava a udržiavanie majetku | I73: 6 | J73: 1 | K73: =VLOOKUP(G73,$L$9:$N$101,2,0) -> #N/A | L73: =LEFT(M73,7) -> 18/0092 | M73: 18/0092 VEKOMA Dsrkride test track
B74: =LEFT(C74,7) -> 18/0107 | C74: 18/0107 VEM Pressrig | D74: =IFERROR(VLOOKUP(B74,$G$8:$I$1048576,3,0),0) -> 0 | F74: 5_režijné zákazky | G74: 26/5006 | H74: Čistenie roštov VP5 | I74: 4 | J74: 1 | K74: =VLOOKUP(G74,$L$9:$N$101,2,0) -> #N/A | L74: =LEFT(M74,7) -> 18/0093 | M74: 18/0093 VEKOMA Minetrain Poland
B75: =LEFT(C75,7) -> 18/0108 | C75: 18/0108 VEM Stator | D75: =IFERROR(VLOOKUP(B75,$G$8:$I$1048576,3,0),0) -> 0 | F75: 5_režijné zákazky | G75: 26/5004 | H75: Plazma skúšky rezov | I75: 2.5 | J75: 1 | K75: =VLOOKUP(G75,$L$9:$N$101,2,0) -> #N/A | L75: =LEFT(M75,7) -> 18/0094 | M75: 18/0094 BRUSH Bearing shield
B76: =LEFT(C76,7) -> 18/0109 | C76: 18/0109 VEM Stator | D76: =IFERROR(VLOOKUP(B76,$G$8:$I$1048576,3,0),0) -> 0 | F76: 5_režijné zákazky | G76: 26/5005 | H76: VRTB náklady na pracovisko | I76: 8 | J76: 2 | K76: =VLOOKUP(G76,$L$9:$N$101,2,0) -> #N/A | L76: =LEFT(M76,7) -> 18/0095 | M76: 18/0095 BRUSH Stator
B77: =LEFT(C77,7) -> 18/0110 | C77: 18/0110 VEKOMA Montáž motorov Family Coaster | D77: =IFERROR(VLOOKUP(B77,$G$8:$I$1048576,3,0),0) -> 0 | F77: 5_režijné zákazky Celková hodnota | I77: 20.5 | J77: 5 | K77: =VLOOKUP(G77,$L$9:$N$101,2,0) -> #N/A | L77: =LEFT(M77,7) -> 18/0096 | M77: 18/0096 VEM Stator
B78: =LEFT(C78,7) -> 18/0111 | C78: 18/0111 VEKOMA Sausalito Coaster | D78: =IFERROR(VLOOKUP(B78,$G$8:$I$1048576,3,0),0) -> 0 | F78: 9_podnik. Réžia | G78: XX/9999 | H78: Podniková réžia | I78: 259 | J78: 10 | K78: =VLOOKUP(G78,$L$9:$N$101,2,0) -> #N/A | L78: =LEFT(M78,7) -> 18/0097 | M78: 18/0097 BRUSH CZ Kostra statora
B79: =LEFT(C79,7) -> 18/0112 | C79: 18/0112 ZIERER Dráha Force 280 | D79: =IFERROR(VLOOKUP(B79,$G$8:$I$1048576,3,0),0) -> 0 | F79: 9_podnik. Réžia Celková hodnota | I79: 259 | J79: 10 | K79: =VLOOKUP(G79,$L$9:$N$101,2,0) -> #N/A | L79: =LEFT(M79,7) -> 18/0099 | M79: 18/0099 VEM Gehäuse
B80: =LEFT(C80,7) -> 18/0114 | C80: 18/0114 ZIERER Lávky_FORCE 280 | D80: =IFERROR(VLOOKUP(B80,$G$8:$I$1048576,3,0),0) -> 0 | F80: 7_Vyskum_a_vyvoj | G80: XX/9999 | H80: Podniková réžia | K80: =VLOOKUP(G80,$L$9:$N$101,2,0) -> #N/A | L80: =LEFT(M80,7) -> 18/0100 | M80: 18/0100 VEKOMA Oprava lávky
B81: =LEFT(C81,7) -> 18/0116 | C81: 18/0116 VEM Stator | D81: =IFERROR(VLOOKUP(B81,$G$8:$I$1048576,3,0),0) -> 0 | F81: 7_Vyskum_a_vyvoj | G81: XX/9999 | H81: (prázdne) | K81: =VLOOKUP(G81,$L$9:$N$101,2,0) -> #N/A | L81: =LEFT(M81,7) -> 18/0103 | M81: 18/0103 BRUSH Stator for a DG
B82: =LEFT(C82,7) -> 18/0117 | C82: 18/0117 BRUSH_2x_bearing shield | D82: =IFERROR(VLOOKUP(B82,$G$8:$I$1048576,3,0),0) -> 0 | F82: 7_Vyskum_a_vyvoj | G82: XX/9999 | H82: Gehäuse 2 ks | K82: =VLOOKUP(G82,$L$9:$N$101,2,0) -> #N/A | L82: =LEFT(M82,7) -> 18/0104 | M82: 18/0104 GERSTLAUER Stĺpy
B83: =LEFT(C83,7) -> 18/0118 | C83: 18/0118 VEKOMA Stator | D83: =IFERROR(VLOOKUP(B83,$G$8:$I$1048576,3,0),0) -> 0 | F83: 7_Vyskum_a_vyvoj | G83: XX/9999 | H83: Gehäuse 1 ks | K83: =VLOOKUP(G83,$L$9:$N$101,2,0) -> #N/A | L83: =LEFT(M83,7) -> 18/0105 | M83: 18/0105 VEM Stator
B84: =LEFT(C84,7) -> 18/0120 | C84: 18/0120 BRUSH SEM_1x_stator | D84: =IFERROR(VLOOKUP(B84,$G$8:$I$1048576,3,0),0) -> 0 | F84: 7_Vyskum_a_vyvoj | G84: XX/9999 | H84: Oprava a udržiavanie majetku | K84: =VLOOKUP(G84,$L$9:$N$101,2,0) -> #N/A | L84: =LEFT(M84,7) -> 18/0106 | M84: 18/0106 VEM Stator
